#### node错误监控

1. 同步方法中的错误: try{}catch(){}

2. 异步回调捕获err，大多数接受callback函数的异步回调都将接受作为第一个参数传给该函数的 Error 对象。

```js
const fs = require('fs');
fs.readFile('a file that does not exist', (err, data) => {
  if (err) {
    console.error('There was an error reading the file!', err);
    return;
  }
  // 否则处理数据
});
```

3. 全局统一监听错误

```js

process.on('uncaughtException', (err) => {
  console.error('uncaught', err)
})
 
process.on('unhandledRejection', (reason, p) => {
  console.error('unhandle', reason, p)

```

当在 EventEmitter 对象上调用异步方法时，错误可以路由到该对象的 'error' 事件

```js
const net = require('net');
const connection = net.connect('localhost');

// 向流中添加 'error' 事件句柄：
connection.on('error', (err) => {
  // 如果连接被服务器重置，
  // 或者根本无法连接，或者连接遇到任何类型的错误，
  // 则错误将发送到这里。
  console.error(err);
});

connection.pipe(process.stdout);
```

#### Node中遇到错误，进程退出了怎么办

1. 捕获uncaughtException

```js
process.on('uncaughtException', (err) => {
  console.error('uncaught', err);
  console.log(err.stack); // 打印错误堆栈
})
```
2. 使用守护进程

可使用node-forever/pm2.

#### node中的错误类型

在node环境中运行的应用，主要会遇到以下4类错误:

1. 标准的 JavaScript 错误，例如EvalError、SyntaxError、RangeError、ReferenceError、TypeError 和 URIError
2. 由底层操作系统约束触发的系统错误，例如尝试打开不存在的文件或尝试通过关闭的套接字发送数据
3. 由应用程序代码触发的用户指定的错误
4. AssertionError是特殊的错误类，当 Node.js 检测到不应该发生的异常逻辑违规时会触发